<?xml version="1.0" ?>
<!-- =================================================================================== -->
<!-- |    This document was autogenerated by xacro from /home/bohg_local/ARM/mandy/control/arm_robot_model/models/DarpaRobot.urdf.xacro | -->
<!-- |    EDITING THIS FILE BY HAND IS NOT RECOMMENDED                                 | -->
<!-- =================================================================================== -->
<!--
 * COPYRIGHT (C) 2010
 * RE2, INC.
 *
 * Author: RE2
 *
 * This file is a part of RobotModel, which was developed for the
 * DARPA ARM ROBOT Track C project.
 *
 * RobotModel is free software:
 * you can redistribute it and/or modify it under the terms of the GNU General
 * Public License as published by the Free Software Foundation, either version
 * 3 of the License, or (at your option) any later version.
 *
 * You should have received a copy of the GNU General Public License along
 * with this package.  If not, see <http://www.gnu.org/licenses/>.
 *
 * RE2, INC. disclaims all warranties with regard to this software, including
 * all implied warranties of merchantability and fitness, in no event shall
 * RE2, INC. be liable for any special, indirect or consequential damages or
 * any damages whatsoever resulting from loss of use, data or profits, whether
 * in an action of contract, negligence or other tortious action, arising out
 * of or in connection with the use or performance of this software.
-->
<robot name="darpa_arm_robot" xmlns:body="http://playerstage.sourceforge.net/gazebo/xmlschema/#body" xmlns:controller="http://playerstage.sourceforge.net/gazebo/xmlschema/#controller" xmlns:geom="http://playerstage.sourceforge.net/gazebo/xmlschema/#geom" xmlns:interface="http://playerstage.sourceforge.net/gazebo/xmlschema/#interface" xmlns:joint="http://playerstage.sourceforge.net/gazebo/xmlschema/#slider" xmlns:sensor="http://playerstage.sourceforge.net/gazebo/xmlschema/#sensor" xmlns:xacro="http://ros.org/wiki/xacro">
  <material name="DarpaGrey">
    <color rgba="0.9 0.9 0.9 1.0"/>
  </material>
  <material name="DarpaBlue">
    <color rgba="0.0 0.5 0.5 1.0"/>
  </material>
  <link name="BASE"/>
  <link name="CYLINDER">
    <inertial>
      <origin rpy="0 0 0" xyz="0 0 0"/>
      <mass value="1.0"/>
      <inertia ixx="1.0" ixy="0.0" ixz="0.0" iyy="100.0" iyz="0.0" izz="1.0"/>
    </inertial>
    <visual>
      <material name="DarpaGrey"/>
      <origin rpy="0 0 0" xyz="0 0 0"/>
      <geometry>
        <cylinder length="0.81337" radius="0.1016"/>
      </geometry>
    </visual>
    <collision>
      <origin rpy="0 0 0" xyz="0 0 0"/>
      <geometry>
        <cylinder length="0.81337" radius="0.1016"/>
      </geometry>
    </collision>
  </link>
  <gazebo reference="CYLINDER">
    <material>
                PR2/Grey2
            </material>
    <turnGravityOff>
                true
            </turnGravityOff>
    <selfCollide>
                true
            </selfCollide>
  </gazebo>
  <link name="TORSO">
    <inertial>
      <origin rpy="0 0 0" xyz="0 0 0"/>
      <mass value="1.0"/>
      <inertia ixx="1.0" ixy="0.0" ixz="0.0" iyy="100.0" iyz="0.0" izz="1.0"/>
    </inertial>
    <visual>
      <material name="DarpaGrey"/>
      <origin rpy="1.57079632679 0 3.14159265359" xyz="0 0 0"/>
      <geometry>
        <mesh filename="package://arm_robot_model/models/componentSTL/baseLinkTwoArms.stl"/>
      </geometry>
    </visual>
    <collision>
      <origin rpy="1.57079632679 0 3.14159265359" xyz="0 0 0"/>
      <geometry>
        <mesh filename="package://arm_robot_model/models/collision/baseLinkTwoArms.stl"/>
      </geometry>
    </collision>
  </link>
  <gazebo reference="TORSO">
    <material>
                PR2/Grey2
            </material>
    <turnGravityOff>
                true
            </turnGravityOff>
    <selfCollide>
                true
            </selfCollide>
  </gazebo>
  <joint name="fixedJoint" type="fixed">
    <parent link="BASE"/>
    <child link="CYLINDER"/>
    <origin rpy="0 0 0" xyz="0 0 0.406686"/>
  </joint>
  <joint name="baseJoint" type="fixed">
    <parent link="CYLINDER"/>
    <child link="TORSO"/>
    <origin rpy="0 0 0" xyz="0 0 0.406686"/>
  </joint>
  <gazebo>
    <controller:gazebo_ros_controller_manager name="gazebo_ros_controller_manager" plugin="libgazebo_ros_controller_manager.so">
      <alwaysOn>true</alwaysOn>
      <updateRate>1000.0</updateRate>
    </controller:gazebo_ros_controller_manager>
  </gazebo>
  <!--  offset was -.2186555 before adding sin(45)*.186 which is needed to put shoulder in right place -->
  <link name="R_SHOULDER">
    <inertial>
      <origin xyz="-.00443422 0.1289039 -.00066489"/>
      <mass value="10.7677"/>
      <inertia ixx=".13488033" ixy="-.00213041" ixz="-.00012485" iyy=".11328369" iyz=".00068555" izz=".09046330"/>
    </inertial>
    <visual>
      <material name="DarpaGrey"/>
      <origin rpy="3.14159265359 0 0" xyz="0 .189 0"/>
      <geometry>
        <mesh filename="package://arm_robot_model/models/componentSTL/wamShoulderLink1.stl"/>
      </geometry>
    </visual>
    <collision>
      <origin rpy="3.14159265359 0 0" xyz="0 .189 0"/>
      <geometry>
        <mesh filename="package://arm_robot_model/models/collision/wamShoulderLink1.stl"/>
      </geometry>
    </collision>
  </link>
  <gazebo reference="R_SHOULDER">
    <material>
                PR2/Grey2
            </material>
    <turnGravityOff>
                true
            </turnGravityOff>
    <selfCollide>
                true
            </selfCollide>
  </gazebo>
  <transmission name="DarmSim_RArm_WAM_ShoulderYaw_trans" type="pr2_mechanism_model/SimpleTransmission">
    <actuator name="DarmSim_RArm_WAM_ShoulderYaw_motor"/>
    <joint name="DarmSim/RArm/WAM/YawJoint"/>
    <mechanicalReduction>1</mechanicalReduction>
    <motorTorqueConstant>1</motorTorqueConstant>
    <pulsesPerRevolution>90000</pulsesPerRevolution>
  </transmission>
  <link name="R_UPPER_ARM_IN_SHOULDER">
    <visual>
      <material name="DarpaGrey"/>
      <origin rpy="3.14159265359 0 0" xyz="0 0 0"/>
      <geometry>
        <mesh filename="package://arm_robot_model/models/componentSTL/wamUpperArmInShoulderLink2.stl"/>
      </geometry>
    </visual>
    <inertial>
      <origin xyz="-.00236981 .03105614 .01542114"/>
      <mass value="3.87493756"/>
      <inertia ixx=".02140958" ixy=".00027172" ixz=".00002461" iyy=".01377875" iyz="-.00181920" izz=".01558906"/>
    </inertial>
    <collision>
      <origin rpy="3.14159265359 0 0" xyz="0 0 0"/>
      <geometry>
        <mesh filename="package://arm_robot_model/models/collision/wamUpperArmInShoulderLink2.stl"/>
      </geometry>
    </collision>
  </link>
  <gazebo reference="R_UPPER_ARM_IN_SHOULDER">
    <material>
                PR2/Grey2
            </material>
    <turnGravityOff>
                true
            </turnGravityOff>
    <selfCollide>
                true
            </selfCollide>
  </gazebo>
  <transmission name="DarmSim_RArm_WAM_ShoulderPitch_trans" type="pr2_mechanism_model/SimpleTransmission">
    <actuator name="DarmSim_RArm_WAM_ShoulderPitch_motor"/>
    <joint name="R_Arm_ShoulderPitchJoint"/>
    <mechanicalReduction>1</mechanicalReduction>
    <motorTorqueConstant>1</motorTorqueConstant>
    <pulsesPerRevolution>90000</pulsesPerRevolution>
  </transmission>
  <link name="R_UPPER_ARM">
    <inertial>
      <origin xyz="-.03826 .20751 .00003"/>
      <mass value="1.80228141"/>
      <inertia ixx=".05911077" ixy="-.00249612" ixz=".00000738" iyy=".00324550" iyz="-.00001767" izz=".05927043"/>
    </inertial>
    <visual>
      <material name="DarpaGrey"/>
      <origin rpy="0 0 0" xyz="0 0 0"/>
      <geometry>
        <mesh filename="package://arm_robot_model/models/componentSTL/wamUpperArmLink3.stl"/>
      </geometry>
    </visual>
    <collision>
      <origin rpy="0 0 0" xyz="0 0 0"/>
      <geometry>
        <mesh filename="package://arm_robot_model/models/collision/wamUpperArmLink3.stl"/>
      </geometry>
    </collision>
  </link>
  <gazebo reference="R_UPPER_ARM">
    <material>
                PR2/Grey2
            </material>
    <turnGravityOff>
                true
            </turnGravityOff>
    <selfCollide>
                true
            </selfCollide>
  </gazebo>
  <transmission name="DarmSim_RArm_WAM_UpperArmYaw_trans" type="pr2_mechanism_model/SimpleTransmission">
    <actuator name="DarmSim_RArm_WAM_UpperArmYaw_motor"/>
    <joint name="R_Arm_ShoulderYawJoint"/>
    <mechanicalReduction>1</mechanicalReduction>
    <motorTorqueConstant>1</motorTorqueConstant>
    <pulsesPerRevolution>90000</pulsesPerRevolution>
  </transmission>
  <link name="R_FOREARM">
    <inertial>
      <origin xyz="0 0 0"/>
      <mass value="2.40016804"/>
      <origin rpy="0 0 0" xyz="-0.04001488 -.00022942 .13271662"/>
      <inertia ixx="0.01491672" ixy="0.00001741" ixz="-0.00150604" iyy="0.01482988" iyz="-0.00002109" izz="0.00294463"/>
    </inertial>
    <visual>
      <material name="DarpaGrey"/>
      <origin rpy="-3.14159265359 0 0" xyz="0 0 0"/>
      <geometry>
        <mesh filename="package://arm_robot_model/models/componentSTL/wamForeArmLink4.stl"/>
      </geometry>
    </visual>
    <collision>
      <origin rpy="-3.14159265359 0 0" xyz="0 0 0"/>
      <geometry>
        <mesh filename="package://arm_robot_model/models/collision/wamForeArmLink4.stl"/>
      </geometry>
    </collision>
  </link>
  <gazebo reference="R_FOREARM">
    <material>
                PR2/Grey2
            </material>
    <turnGravityOff>
                true
            </turnGravityOff>
    <selfCollide>
                true
            </selfCollide>
  </gazebo>
  <transmission name="DarmSim_RArm_WAM_ElbowPitch_trans" type="pr2_mechanism_model/SimpleTransmission">
    <actuator name="DarmSim_RArm_WAM_ElbowPitch_motor"/>
    <joint name="DarmSim/RArm/WAM/ElbowJoint"/>
    <mechanicalReduction>1</mechanicalReduction>
    <motorTorqueConstant>1</motorTorqueConstant>
    <pulsesPerRevolution>90000</pulsesPerRevolution>
  </transmission>
  <link name="R_UPPER_WRIST_YAW">
    <inertial>
      <origin xyz="0.00008921 0.00511217 0.00435824"/>
      <mass value="0.12376019"/>
      <inertia ixx="0.00005029" ixy="0.00000020" ixz="0.00007582" iyy="0.00007582" iyz="-0.00000359" izz="0.00006270"/>
    </inertial>
    <visual>
      <material name="DarpaGrey"/>
      <origin rpy="3.14159265359 0 0" xyz="0 0.02711 0"/>
      <geometry>
        <mesh filename="package://arm_robot_model/models/componentSTL/wamUpperWristYawLink5.stl"/>
      </geometry>
    </visual>
    <collision>
      <origin rpy="3.14159265359 0 0" xyz="0 0.02711 0"/>
      <geometry>
        <mesh filename="package://arm_robot_model/models/collision/wamUpperWristYawLink5.stl"/>
      </geometry>
    </collision>
  </link>
  <gazebo reference="R_UPPER_WRIST_YAW">
    <material>
                PR2/Grey2
            </material>
    <turnGravityOff>
                true
            </turnGravityOff>
    <selfCollide>
                true
            </selfCollide>
  </gazebo>
  <transmission name="DarmSim_RArm_WAM_UpperWristYaw_trans" type="pr2_mechanism_model/SimpleTransmission">
    <actuator name="DarmSim_RArm_WAM_UpperWristYaw_motor"/>
    <joint name="DarmSim/RArm/WAM/UpperWristYawJoint"/>
    <mechanicalReduction>1</mechanicalReduction>
    <motorTorqueConstant>1</motorTorqueConstant>
    <pulsesPerRevolution>90000</pulsesPerRevolution>
  </transmission>
  <link name="R_UPPER_WRIST_PITCH">
    <inertial>
      <origin rpy="0 0 0" xyz="-0.00012262 -0.01703194 0.02468336"/>
      <mass value="0.41797364"/>
      <inertia ixx="0.00055516" ixy="0.00000061" ixz="-0.00000074" iyy="0.00024367" iyz="-0.00004590" izz="0.00045358"/>
    </inertial>
    <visual>
      <material name="DarpaGrey"/>
      <origin rpy="1.57079632679 0 1.57079632679" xyz="0 0 0"/>
      <geometry>
        <mesh filename="package://arm_robot_model/models/componentSTL/wamUpperWristPitchLink6.stl"/>
      </geometry>
    </visual>
    <collision>
      <origin rpy="1.57079632679 0 1.57079632679" xyz="0 0 0"/>
      <geometry>
        <mesh filename="package://arm_robot_model/models/collision/wamUpperWristPitchLink6.stl"/>
      </geometry>
    </collision>
  </link>
  <gazebo reference="R_UPPER_WRIST_PITCH">
    <material>
                PR2/Grey2
            </material>
    <turnGravityOff>
                true
            </turnGravityOff>
    <selfCollide>
                true
            </selfCollide>
  </gazebo>
  <transmission name="DarmSim_RArm_WAM_UpperWristPitch_trans" type="pr2_mechanism_model/SimpleTransmission">
    <actuator name="DarmSim_RArm_WAM_UpperWristPitch_motor"/>
    <joint name="DarmSim/RArm/WAM/UpperWristPitchJoint"/>
    <mechanicalReduction>1</mechanicalReduction>
    <motorTorqueConstant>1</motorTorqueConstant>
    <pulsesPerRevolution>90000</pulsesPerRevolution>
  </transmission>
  <link name="R_LOWER_WRIST">
    <inertial>
      <origin xyz="0.00035500 -0.00499005 0.04864979"/>
      <mass value="0.63352875"/>
      <inertia ixx="0.00102103" ixy="0.00000775" ixz="-0.00001230" iyy="0.00080944" iyz="-0.00014417" izz="0.00068788"/>
    </inertial>
    <visual>
      <material name="DarpaGrey"/>
      <origin rpy="1.57079632679 0 0" xyz="0 0 0"/>
      <geometry>
        <mesh filename="package://arm_robot_model/models/componentSTL/wamLowerWristFTPalmLink7.stl"/>
      </geometry>
    </visual>
    <collision>
      <origin rpy="1.57079632679 0 0" xyz="0 0 0"/>
      <geometry>
        <mesh filename="package://arm_robot_model/models/collision/wamLowerWristFTPalmLink7.stl"/>
      </geometry>
    </collision>
  </link>
  <gazebo reference="R_LOWER_WRIST">
    <material>
                PR2/Grey2
            </material>
    <turnGravityOff>
                true
            </turnGravityOff>
    <selfCollide>
                true
            </selfCollide>
  </gazebo>
  <transmission name="DarmSim_RArm_WAM_LowerWristYaw_trans" type="pr2_mechanism_model/SimpleTransmission">
    <actuator name="DarmSim_RArm_WAM_LowerWristYaw_motor"/>
    <joint name="DarmSim/RArm/WAM/LowerWristYawJoint"/>
    <mechanicalReduction>1</mechanicalReduction>
    <motorTorqueConstant>1</motorTorqueConstant>
    <pulsesPerRevolution>90000</pulsesPerRevolution>
  </transmission>
  <link name="R_PALM"/>
  <link name="R_FORCE_TORQUE_SENSOR"/>
  <joint name="R_SFE" type="revolute">
    <parent link="TORSO"/>
    <child link="R_SHOULDER"/>
    <origin rpy="-1.57079632679 -1.57079632679 3.92699081699" xyz="0.350177361 0.350177361 .37836125"/>
    <axis xyz="0 -1.0 0"/>
    <limit effort="25" lower="-2.67" upper="2.66" velocity="3.27"/>
    <!--
            <safety_controller k_position="10000000" k_velocity="10000000" soft_lower_limit="-100.0" soft_upper_limit="100.0" />
-->
    <dynamics damping="1.0" friction="100.0"/>
  </joint>
  <joint name="R_SAA" type="revolute">
    <parent link="R_SHOULDER"/>
    <child link="R_UPPER_ARM_IN_SHOULDER"/>
    <!--<origin xyz="0 0 0" rpy="${0.5 * PI} 0 0"/>-->
    <origin rpy="1.57079632679 0 -1.570796" xyz="0 0 0"/>
    <axis xyz="0 -1 0"/>
    <limit effort="20" lower="-3.47" upper="0.4" velocity="3.27"/>
    <!--
            <safety_controller k_position="100" k_velocity="3" soft_lower_limit="-100.0" soft_upper_limit="100.0" />
-->
    <dynamics damping="1.0" friction="100.0"/>
  </joint>
  <joint name="R_HR" type="revolute">
    <parent link="R_UPPER_ARM_IN_SHOULDER"/>
    <child link="R_UPPER_ARM"/>
    <origin rpy="-1.57079632679 0 -0.785398" xyz="0 0 0"/>
    <axis xyz="0 -1.0 0"/>
    <limit effort="15" lower="-5.18" upper="0.43" velocity="3.27"/>
    <!--
            <safety_controller k_position="100" k_velocity="3" soft_lower_limit="-100.0" soft_upper_limit="100.0" />
-->
    <dynamics damping="1.0" friction="100.0"/>
  </joint>
  <joint name="R_EB" type="revolute">
    <parent link="R_UPPER_ARM"/>
    <child link="R_FOREARM"/>
    <origin rpy="1.57079632679 0 0.0" xyz="0.045 -0.55 0"/>
    <axis xyz="0 1 0"/>
    <limit effort="15" lower="-0.85" upper="3.11" velocity="3.27"/>
    <!--
            <safety_controller k_position="100" k_velocity="3" soft_lower_limit="-100.0" soft_upper_limit="100.0" />
-->
    <dynamics damping="1.0" friction="100.0"/>
  </joint>
  <joint name="R_WR" type="revolute">
    <parent link="R_FOREARM"/>
    <child link="R_UPPER_WRIST_YAW"/>
    <origin rpy="-1.57079632679 0 3.26794896477e-07" xyz="-0.045 0 .3"/>
    <axis xyz="0 -1.0 0"/>
    <limit effort="5" lower="-3.18" upper="2.0" velocity="3.27"/>
    <!--
            <safety_controller k_position="100" k_velocity="3" soft_lower_limit="-100.0" soft_upper_limit="100.0" />
-->
    <dynamics damping="1.0" friction="100.0"/>
  </joint>
  <joint name="R_WFE" type="revolute">
    <parent link="R_UPPER_WRIST_YAW"/>
    <child link="R_UPPER_WRIST_PITCH"/>
    <origin rpy="1.57079632679 1.57079632679 0.0" xyz="0 0 0"/>
    <axis xyz="0 1 0"/>
    <limit effort="5" lower="-1.52" upper="1.52" velocity="3.27"/>
    <!-- 1.45 is a limit taken in from 1.5 due to saftey and differences between arms. -->
    <!--
            <safety_controller k_position="100" k_velocity="3" soft_lower_limit="-100.0" soft_upper_limit="100.0" />
-->
    <dynamics damping="1.0" friction="100.0"/>
  </joint>
  <joint name="R_WAA" type="revolute">
    <parent link="R_UPPER_WRIST_PITCH"/>
    <child link="R_LOWER_WRIST"/>
    <origin rpy="0 0 -1.57079632679" xyz="0 0 0.04795"/>
    <axis xyz="0 0 1.0"/>
    <limit effort="5" lower="-2.96" upper="2.99" velocity="3.27"/>
    <!-- 2.95 is a limit taken in from 3 due to saftey and differences between arms. -->
    <!--
            <safety_controller k_position="100" k_velocity="3" soft_lower_limit="-100.0" soft_upper_limit="100.0" />
-->
    <dynamics damping="1.0" friction="100.0"/>
  </joint>
  <joint name="R_Arm_ForceTorqueJoint" type="fixed">
    <parent link="R_LOWER_WRIST"/>
    <child link="R_FORCE_TORQUE_SENSOR"/>
    <origin rpy="0 0 1.57079632679" xyz="0 0 0.0131834"/>
    <!-- 0.0131834 = .0059834 from wrist to f-t + .0072 from ft to sensor origin-->
  </joint>
  <joint name="R_Arm_PalmJoint" type="fixed">
    <parent link="R_LOWER_WRIST"/>
    <child link="R_PALM"/>
    <origin rpy="0 0 3.14159265359" xyz="0 0 0.1033"/>
  </joint>
  <link name="R_HAND_M_FINGER_KNUCKLE_2">
    <visual>
      <material name="DarpaGrey"/>
      <origin rpy="3.14159265359 1.57079632679 0" xyz="0 0 0"/>
      <geometry>
        <mesh filename="package://arm_robot_model/models/componentSTL/secondFingerLink.stl"/>
      </geometry>
    </visual>
    <inertial>
      <origin xyz=".031720 .001070 -.000586"/>
      <mass value="0.057957"/>
      <inertia ixx="0.00000461" ixy="0.00000003" ixz="0.00000164" iyy="0.00003590" iyz="0.00000004" izz="0.00003682"/>
    </inertial>
    <collision>
      <origin rpy="3.14159265359 1.57079632679 0" xyz="0 0 0"/>
      <geometry>
        <mesh filename="package://arm_robot_model/models/collision/secondFingerLink.stl"/>
      </geometry>
      <mu1 value="50000.0"/>
      <mu2 value="50000.0"/>
      <kp value="1000000.0"/>
      <kd value="1.0"/>
    </collision>
  </link>
  <gazebo reference="R_HAND_M_FINGER_KNUCKLE_2">
    <material>
                PR2/Grey2
            </material>
    <turnGravityOff>
                true
            </turnGravityOff>
    <selfCollide>
                true
            </selfCollide>
  </gazebo>
  <transmission name="DarmSim_RArm_BHand_FingerMKnuckleTwo_trans" type="pr2_mechanism_model/SimpleTransmission">
    <actuator name="DarmSim_RArm_BHand_FingerMKnuckleTwo_motor"/>
    <joint name="R_Arm_M_Finger_KnuckleTwoJoint"/>
    <mechanicalReduction>1</mechanicalReduction>
    <motorTorqueConstant>1</motorTorqueConstant>
    <pulsesPerRevolution>90000</pulsesPerRevolution>
  </transmission>
  <link name="R_HAND_M_FINGER_KNUCKLE_3">
    <visual>
      <material name="DarpaGrey"/>
      <origin rpy="0 1.57079632679 0" xyz="0 0 0"/>
      <geometry>
        <mesh filename="package://arm_robot_model/models/componentSTL/thirdFingerLink.stl"/>
      </geometry>
    </visual>
    <inertial>
      <origin xyz="0.01970974 0.00182016 0.00020041"/>
      <mass value="0.03421781"/>
      <inertia ixx="0.00000287" ixy="0.00000091" ixz="-0.00000007" iyy="0.00001329" iyz="-0.00000002" izz="0.00001214"/>
    </inertial>
    <collision>
      <origin rpy="0 1.57079632679 0" xyz="0 0 0"/>
      <geometry>
        <mesh filename="package://arm_robot_model/models/collision/thirdFingerLink.stl"/>
      </geometry>
      <mu1 value="50000.0"/>
      <mu2 value="50000.0"/>
      <kp value="1000000.0"/>
      <kd value="1.0"/>
    </collision>
  </link>
  <gazebo reference="R_HAND_M_FINGER_KNUCKLE_3">
    <material>
                PR2/Grey2
            </material>
    <turnGravityOff>
                true
            </turnGravityOff>
    <selfCollide>
                true
            </selfCollide>
  </gazebo>
  <transmission name="DarmSim_RArm_BHand_FingerMKnuckleThree_trans" type="pr2_mechanism_model/SimpleTransmission">
    <actuator name="DarmSim_RArm_BHand_FingerMKnuckleThree_motor"/>
    <joint name="R_Arm_M_Finger_KnuckleThreeJoint"/>
    <mechanicalReduction>1</mechanicalReduction>
    <motorTorqueConstant>1</motorTorqueConstant>
    <pulsesPerRevolution>90000</pulsesPerRevolution>
  </transmission>
  <link name="R_HAND_M_FINGER_TIP"/>
  <joint name="R_MF" type="revolute">
    <parent link="R_LOWER_WRIST"/>
    <child link="R_HAND_M_FINGER_KNUCKLE_2"/>
    <origin rpy="-1.57079632679 -0.0429350996 -1.57079632679" xyz="0 -0.05 0.09938"/>
    <axis xyz="0 0 -1"/>
    <limit effort="1" lower="0" upper="2.12232037299" velocity="3.27"/>
    <dynamics damping="0.005" friction="100.0"/>
  </joint>
  <joint name="R_MF2" type="revolute">
    <parent link="R_HAND_M_FINGER_KNUCKLE_2"/>
    <child link="R_HAND_M_FINGER_KNUCKLE_3"/>
    <origin rpy="0 0 0" xyz="0.07 0 0"/>
    <!--<origin xyz="0.07 0 0" rpy="0 0 -0.733038286"/>-->
    <axis xyz="0 0 -1"/>
    <limit effort="1" lower="0" upper="0.907571214" velocity="3.27"/>
    <dynamics damping="0.005" friction="100.0"/>
    <!--<mimic joint="${side}_${number}F" multiplier="1" offset="0"/>-->
  </joint>
  <joint name="R_MF3" type="fixed">
    <parent link="R_HAND_M_FINGER_KNUCKLE_3"/>
    <child link="R_HAND_M_FINGER_TIP"/>
    <origin rpy="0 0 0" xyz="0.056 0 0"/>
  </joint>
  <link name="R_HAND_L_FINGER_KNUCKLE_1">
    <visual>
      <material name="DarpaGrey"/>
      <origin rpy="1.57079632679 0 -1.57079632679" xyz="0 0 0"/>
      <geometry>
        <mesh filename="package://arm_robot_model/models/componentSTL/firstFingerLink.stl"/>
      </geometry>
      <mu1 value="50000.0"/>
      <mu2 value="50000.0"/>
      <kp value="1000000.0"/>
      <kd value="1.0"/>
    </visual>
    <inertial>
      <origin xyz="0.03201666 -0.00086502 0.00890075"/>
      <mass value="0.16252678"/>
      <inertia ixx="0.00002567" ixy="-0.00000146" ixz="0.00001128" iyy="0.00008818" iyz="-0.00000094" izz="0.00007827"/>
    </inertial>
    <collision>
      <origin rpy="1.57079632679 0 -1.57079632679" xyz="0 0 0"/>
      <geometry>
        <mesh filename="package://arm_robot_model/models/collision/firstFingerLink.stl"/>
      </geometry>
    </collision>
  </link>
  <gazebo reference="R_HAND_L_FINGER_KNUCKLE_1">
    <material>
                PR2/Grey2
            </material>
    <turnGravityOff>
                true
            </turnGravityOff>
    <selfCollide>
                true
            </selfCollide>
  </gazebo>
  <transmission name="DarmSim_RArm_BHand_FingerOneKnuckleOne_trans" type="pr2_mechanism_model/SimpleTransmission">
    <actuator name="DarmSim_RArm_BHand_FingerOneKnuckleOne_motor"/>
    <joint name="R_Arm_FingerOne_KnuckleOneJoint"/>
    <mechanicalReduction>1</mechanicalReduction>
    <motorTorqueConstant>1</motorTorqueConstant>
    <pulsesPerRevolution>90000</pulsesPerRevolution>
  </transmission>
  <link name="R_HAND_L_FINGER_KNUCKLE_2">
    <visual>
      <material name="DarpaGrey"/>
      <origin rpy="3.14159265359 1.57079632679 0" xyz="0 0 0"/>
      <geometry>
        <mesh filename="package://arm_robot_model/models/componentSTL/secondFingerLink.stl"/>
      </geometry>
    </visual>
    <inertial>
      <origin xyz=".031720 .001070 -.000586"/>
      <mass value="0.057957"/>
      <inertia ixx="0.00000461" ixy="0.00000003" ixz="0.00000164" iyy="0.00003590" iyz="0.00000004" izz="0.00003682"/>
    </inertial>
    <collision>
      <origin rpy="3.14159265359 1.57079632679 0" xyz="0 0 0"/>
      <geometry>
        <mesh filename="package://arm_robot_model/models/collision/secondFingerLink.stl"/>
      </geometry>
      <mu1 value="50000.0"/>
      <mu2 value="50000.0"/>
      <kp value="1000000.0"/>
      <kd value="1.0"/>
    </collision>
  </link>
  <gazebo reference="R_HAND_L_FINGER_KNUCKLE_2">
    <material>
                PR2/Grey2
            </material>
    <turnGravityOff>
                true
            </turnGravityOff>
    <selfCollide>
                true
            </selfCollide>
  </gazebo>
  <transmission name="DarmSim_RArm_BHand_FingerLKnuckleTwo_trans" type="pr2_mechanism_model/SimpleTransmission">
    <actuator name="DarmSim_RArm_BHand_FingerLKnuckleTwo_motor"/>
    <joint name="R_Arm_L_Finger_KnuckleTwoJoint"/>
    <mechanicalReduction>1</mechanicalReduction>
    <motorTorqueConstant>1</motorTorqueConstant>
    <pulsesPerRevolution>90000</pulsesPerRevolution>
  </transmission>
  <link name="R_HAND_L_FINGER_KNUCKLE_3">
    <visual>
      <material name="DarpaGrey"/>
      <origin rpy="0 1.57079632679 0" xyz="0 0 0"/>
      <geometry>
        <mesh filename="package://arm_robot_model/models/componentSTL/thirdFingerLink.stl"/>
      </geometry>
    </visual>
    <inertial>
      <origin xyz="0.01970974 0.00182016 0.00020041"/>
      <mass value="0.03421781"/>
      <inertia ixx="0.00000287" ixy="0.00000091" ixz="-0.00000007" iyy="0.00001329" iyz="-0.00000002" izz="0.00001214"/>
    </inertial>
    <collision>
      <origin rpy="0 1.57079632679 0" xyz="0 0 0"/>
      <geometry>
        <mesh filename="package://arm_robot_model/models/collision/thirdFingerLink.stl"/>
      </geometry>
      <mu1 value="50000.0"/>
      <mu2 value="50000.0"/>
      <kp value="1000000.0"/>
      <kd value="1.0"/>
    </collision>
  </link>
  <gazebo reference="R_HAND_L_FINGER_KNUCKLE_3">
    <material>
                PR2/Grey2
            </material>
    <turnGravityOff>
                true
            </turnGravityOff>
    <selfCollide>
                true
            </selfCollide>
  </gazebo>
  <transmission name="DarmSim_RArm_BHand_FingerLKnuckleThree_trans" type="pr2_mechanism_model/SimpleTransmission">
    <actuator name="DarmSim_RArm_BHand_FingerLKnuckleThree_motor"/>
    <joint name="R_Arm_L_Finger_KnuckleThreeJoint"/>
    <mechanicalReduction>1</mechanicalReduction>
    <motorTorqueConstant>1</motorTorqueConstant>
    <pulsesPerRevolution>90000</pulsesPerRevolution>
  </transmission>
  <link name="R_HAND_L_FINGER_TIP"/>
  <joint name="R_LF" type="revolute">
    <parent link="R_HAND_L_FINGER_KNUCKLE_1"/>
    <child link="R_HAND_L_FINGER_KNUCKLE_2"/>
    <origin rpy="-1.57079632679 -0.0429350996 0" xyz=".05 0 0.02140"/>
    <axis xyz="0 0 -1"/>
    <limit effort="1" lower="0" upper="2.12232037299" velocity="3.27"/>
    <dynamics damping="0.005" friction="100.0"/>
  </joint>
  <joint name="R_LF2" type="revolute">
    <parent link="R_HAND_L_FINGER_KNUCKLE_2"/>
    <child link="R_HAND_L_FINGER_KNUCKLE_3"/>
    <origin rpy="0 0 0" xyz="0.07 0 0"/>
    <!--<origin xyz="0.07 0 0" rpy="0 0 -0.733038286"/>-->
    <axis xyz="0 0 -1"/>
    <limit effort="1" lower="0" upper="0.907571214" velocity="3.27"/>
    <dynamics damping="0.005" friction="100.0"/>
    <!--<mimic joint="${side}_${number}F" multiplier="1" offset="0"/>-->
  </joint>
  <joint name="R_LF3" type="fixed">
    <parent link="R_HAND_L_FINGER_KNUCKLE_3"/>
    <child link="R_HAND_L_FINGER_TIP"/>
    <origin rpy="0 0 0" xyz="0.056 0 0"/>
  </joint>
  <link name="R_HAND_R_FINGER_KNUCKLE_1">
    <visual>
      <material name="DarpaGrey"/>
      <origin rpy="1.57079632679 0 -1.57079632679" xyz="0 0 0"/>
      <geometry>
        <mesh filename="package://arm_robot_model/models/componentSTL/firstFingerLink.stl"/>
      </geometry>
    </visual>
    <inertial>
      <origin xyz="0.03201666 -0.00086502 0.00890075"/>
      <mass value="0.16252678"/>
      <inertia ixx="0.00002567" ixy="-0.00000146" ixz="0.00001128" iyy="0.00008818" iyz="-0.00000094" izz="0.00007827"/>
    </inertial>
    <collision>
      <origin rpy="1.57079632679 0 -1.57079632679" xyz="0 0 0"/>
      <geometry>
        <mesh filename="package://arm_robot_model/models/collision/firstFingerLink.stl"/>
      </geometry>
    </collision>
  </link>
  <gazebo reference="R_HAND_R_FINGER_KNUCKLE_1">
    <material>
                PR2/Grey2
            </material>
    <turnGravityOff>
                true
            </turnGravityOff>
    <selfCollide>
                true
            </selfCollide>
  </gazebo>
  <transmission name="DarmSim_RArm_BHand_FingerTwoKnuckleOne_trans" type="pr2_mechanism_model/SimpleTransmission">
    <actuator name="DarmSim_RArm_BHand_FingerTwoKnuckleOne_motor"/>
    <joint name="R_Arm_FingerTwo_KnuckleOneJoint"/>
    <mechanicalReduction>1</mechanicalReduction>
    <motorTorqueConstant>1</motorTorqueConstant>
    <pulsesPerRevolution>90000</pulsesPerRevolution>
  </transmission>
  <link name="R_HAND_R_FINGER_KNUCKLE_2">
    <visual>
      <material name="DarpaGrey"/>
      <origin rpy="3.14159265359 1.57079632679 0" xyz="0 0 0"/>
      <geometry>
        <mesh filename="package://arm_robot_model/models/componentSTL/secondFingerLink.stl"/>
      </geometry>
    </visual>
    <inertial>
      <origin xyz=".031720 .001070 -.000586"/>
      <mass value="0.057957"/>
      <inertia ixx="0.00000461" ixy="0.00000003" ixz="0.00000164" iyy="0.00003590" iyz="0.00000004" izz="0.00003682"/>
    </inertial>
    <collision>
      <origin rpy="3.14159265359 1.57079632679 0" xyz="0 0 0"/>
      <geometry>
        <mesh filename="package://arm_robot_model/models/collision/secondFingerLink.stl"/>
      </geometry>
      <mu1 value="50000.0"/>
      <mu2 value="50000.0"/>
      <kp value="1000000.0"/>
      <kd value="1.0"/>
    </collision>
  </link>
  <gazebo reference="R_HAND_R_FINGER_KNUCKLE_2">
    <material>
                PR2/Grey2
            </material>
    <turnGravityOff>
                true
            </turnGravityOff>
    <selfCollide>
                true
            </selfCollide>
  </gazebo>
  <transmission name="DarmSim_RArm_BHand_FingerRKnuckleTwo_trans" type="pr2_mechanism_model/SimpleTransmission">
    <actuator name="DarmSim_RArm_BHand_FingerRKnuckleTwo_motor"/>
    <joint name="R_Arm_R_Finger_KnuckleTwoJoint"/>
    <mechanicalReduction>1</mechanicalReduction>
    <motorTorqueConstant>1</motorTorqueConstant>
    <pulsesPerRevolution>90000</pulsesPerRevolution>
  </transmission>
  <link name="R_HAND_R_FINGER_KNUCKLE_3">
    <visual>
      <material name="DarpaGrey"/>
      <origin rpy="0 1.57079632679 0" xyz="0 0 0"/>
      <geometry>
        <mesh filename="package://arm_robot_model/models/componentSTL/thirdFingerLink.stl"/>
      </geometry>
    </visual>
    <inertial>
      <origin xyz="0.01970974 0.00182016 0.00020041"/>
      <mass value="0.03421781"/>
      <inertia ixx="0.00000287" ixy="0.00000091" ixz="-0.00000007" iyy="0.00001329" iyz="-0.00000002" izz="0.00001214"/>
    </inertial>
    <collision>
      <origin rpy="0 1.57079632679 0" xyz="0 0 0"/>
      <geometry>
        <mesh filename="package://arm_robot_model/models/collision/thirdFingerLink.stl"/>
      </geometry>
      <mu1 value="50000.0"/>
      <mu2 value="50000.0"/>
      <kp value="1000000.0"/>
      <kd value="1.0"/>
    </collision>
  </link>
  <gazebo reference="R_HAND_R_FINGER_KNUCKLE_3">
    <material>
                PR2/Grey2
            </material>
    <turnGravityOff>
                true
            </turnGravityOff>
    <selfCollide>
                true
            </selfCollide>
  </gazebo>
  <transmission name="DarmSim_RArm_BHand_FingerRKnuckleThree_trans" type="pr2_mechanism_model/SimpleTransmission">
    <actuator name="DarmSim_RArm_BHand_FingerRKnuckleThree_motor"/>
    <joint name="R_Arm_R_Finger_KnuckleThreeJoint"/>
    <mechanicalReduction>1</mechanicalReduction>
    <motorTorqueConstant>1</motorTorqueConstant>
    <pulsesPerRevolution>90000</pulsesPerRevolution>
  </transmission>
  <link name="R_HAND_R_FINGER_TIP"/>
  <joint name="R_RF" type="revolute">
    <parent link="R_HAND_R_FINGER_KNUCKLE_1"/>
    <child link="R_HAND_R_FINGER_KNUCKLE_2"/>
    <origin rpy="-1.57079632679 -0.0429350996 0" xyz=".05 0 0.02140"/>
    <axis xyz="0 0 -1"/>
    <limit effort="1" lower="0" upper="2.12232037299" velocity="3.27"/>
    <dynamics damping="0.005" friction="100.0"/>
  </joint>
  <joint name="R_RF2" type="revolute">
    <parent link="R_HAND_R_FINGER_KNUCKLE_2"/>
    <child link="R_HAND_R_FINGER_KNUCKLE_3"/>
    <origin rpy="0 0 0" xyz="0.07 0 0"/>
    <!--<origin xyz="0.07 0 0" rpy="0 0 -0.733038286"/>-->
    <axis xyz="0 0 -1"/>
    <limit effort="1" lower="0" upper="0.907571214" velocity="3.27"/>
    <dynamics damping="0.005" friction="100.0"/>
    <!--<mimic joint="${side}_${number}F" multiplier="1" offset="0"/>-->
  </joint>
  <joint name="R_RF3" type="fixed">
    <parent link="R_HAND_R_FINGER_KNUCKLE_3"/>
    <child link="R_HAND_R_FINGER_TIP"/>
    <origin rpy="0 0 0" xyz="0.056 0 0"/>
  </joint>
  <joint name="R_FR" type="revolute">
    <parent link="R_LOWER_WRIST"/>
    <child link="R_HAND_L_FINGER_KNUCKLE_1"/>
    <origin rpy="0 0 1.57079632679" xyz=".02497 0 0.07798"/>
    <axis xyz="0 0 -1"/>
    <limit effort="1" lower="0" upper="3.14159265359" velocity="3.27"/>
    <dynamics damping="0.005" friction="100.0"/>
  </joint>
  <joint name="R_FR2" type="revolute">
    <parent link="R_LOWER_WRIST"/>
    <child link="R_HAND_R_FINGER_KNUCKLE_1"/>
    <origin rpy="0 0 1.57079632679" xyz="-.02497 0 0.07798"/>
    <axis xyz="0 0 1"/>
    <limit effort="1" lower="0" upper="3.14159265359" velocity="3.27"/>
    <dynamics damping="0.005" friction="100.0"/>
    <mimic joint="R_FR" multiplier="1" offset="0"/>
  </joint>
  <link name="LOWER_PAN_UNIT">
    <inertial>
      <origin xyz="0.00001 0.07282 -0.03237"/>
      <mass value="5.21134"/>
      <inertia ixx="0.01476" ixy="0.00000" ixz="0.00000" iyy="0.01308" iyz="0.00026" izz="0.01292"/>
    </inertial>
    <visual>
      <material name="DarpaGrey"/>
      <origin rpy="0 0 0" xyz="0 0 0"/>
      <geometry>
        <mesh filename="package://arm_robot_model/models/componentSTL/lowerPanUnit.stl"/>
      </geometry>
    </visual>
    <collision>
      <origin rpy="0 0 0" xyz="0 0 0"/>
      <geometry>
        <mesh filename="package://arm_robot_model/models/collision/lowerPanUnit.stl"/>
      </geometry>
    </collision>
  </link>
  <gazebo reference="LOWER_PAN_UNIT">
    <material>
                PR2/Grey2
            </material>
    <turnGravityOff>
                true
            </turnGravityOff>
    <selfCollide>
                true
            </selfCollide>
  </gazebo>
  <transmission name="DarmSim_lowerPan_trans" type="pr2_mechanism_model/SimpleTransmission">
    <actuator name="DarmSim_lowerPan_motor"/>
    <joint name="DarmSim/LowerPanTilt/Pan"/>
    <mechanicalReduction>1</mechanicalReduction>
    <motorTorqueConstant>1</motorTorqueConstant>
    <pulsesPerRevolution>90000</pulsesPerRevolution>
  </transmission>
  <link name="LOWER_TILT_BEAMS">
    <inertial>
      <origin xyz="0 0.05569085 0"/>
      <mass value="0.23295"/>
      <inertia ixx="0.00074525" ixy="0.00000000" ixz="0.00000000" iyy="0.00086895" iyz="0.00000000" izz="0.00151618"/>
    </inertial>
    <visual>
      <material name="DarpaGrey"/>
      <origin rpy="0 0 0" xyz="0 0 0"/>
      <geometry>
        <mesh filename="package://arm_robot_model/models/componentSTL/lowerTiltBeamsLink.stl"/>
      </geometry>
    </visual>
    <collision>
      <origin rpy="0 0 0" xyz="0 0 0"/>
      <geometry>
        <mesh filename="package://arm_robot_model/models/collision/lowerTiltBeamsLink.stl"/>
      </geometry>
    </collision>
  </link>
  <gazebo reference="LOWER_TILT_BEAMS">
    <material>
                PR2/Grey2
            </material>
    <turnGravityOff>
                true
            </turnGravityOff>
    <selfCollide>
                true
            </selfCollide>
  </gazebo>
  <transmission name="DarmSim_lowerTilt_trans" type="pr2_mechanism_model/SimpleTransmission">
    <actuator name="DarmSim_lowerTilt_motor"/>
    <joint name="DarmSim/LowerPanTilt/Tilt"/>
    <mechanicalReduction>1</mechanicalReduction>
    <motorTorqueConstant>1</motorTorqueConstant>
    <pulsesPerRevolution>90000</pulsesPerRevolution>
  </transmission>
  <link name="LOWER_TILT_BEAMS_FRONT">
    <visual>
      <material name="DarpaGrey"/>
      <origin rpy="0 0 0" xyz="0 0 0"/>
      <geometry>
        <mesh filename="package://arm_robot_model/models/componentSTL/lowerTiltBeamsFrontLink.stl"/>
      </geometry>
      <material name="base">
        <color rgba="0 255 255 1.0"/>
      </material>
    </visual>
    <inertial>
      <origin xyz="-0.02081566 0.07765392 0"/>
      <mass value="0.18024349"/>
      <inertia ixx="0.00040661" ixy="0.00004989" ixz="0.0" iyy="0.00008067" iyz="0.0" izz="0.00037761"/>
    </inertial>
    <collision>
      <origin rpy="0 0 0" xyz="0 0 0"/>
      <geometry>
        <mesh filename="package://arm_robot_model/models/collision/lowerTiltBeamsFrontLink.stl"/>
      </geometry>
    </collision>
  </link>
  <gazebo reference="LOWER_TILT_BEAMS_FRONT">
    <material>
                PR2/Grey2
            </material>
    <turnGravityOff>
                true
            </turnGravityOff>
    <selfCollide>
                true
            </selfCollide>
  </gazebo>
  <transmission name="DarmSim_lowerTiltFront_trans" type="pr2_mechanism_model/SimpleTransmission">
    <actuator name="DarmSim_lowerTiltFront_motor"/>
    <joint name="DarmSim/lowerTiltFrontJoint"/>
    <mechanicalReduction>1</mechanicalReduction>
    <motorTorqueConstant>1</motorTorqueConstant>
    <pulsesPerRevolution>90000</pulsesPerRevolution>
  </transmission>
  <link name="LOWER_TILT_BEAMS_TOP">
    <visual>
      <material name="DarpaGrey"/>
      <origin rpy="0 0 0" xyz="0 0 0"/>
      <geometry>
        <mesh filename="package://arm_robot_model/models/componentSTL/lowerTiltBeamsTopLink.stl"/>
      </geometry>
      <material name="base">
        <color rgba="0 255 255 1.0"/>
      </material>
    </visual>
    <inertial>
      <origin xyz="0.00764212 0.02983896 0.02908565"/>
      <mass value="0.86295437"/>
      <inertia ixx="0.00080256" ixy="0.00005477" ixz="-0.00006009" iyy="0.00100235" iyz="0.00000187" izz="0.00074854"/>
    </inertial>
    <collision>
      <origin rpy="0 0 0" xyz="0 0 0"/>
      <geometry>
        <mesh filename="package://arm_robot_model/models/collision/lowerTiltBeamsTopLink.stl"/>
      </geometry>
    </collision>
  </link>
  <gazebo reference="LOWER_TILT_BEAMS_TOP">
    <material>
                PR2/Grey2
            </material>
    <turnGravityOff>
                true
            </turnGravityOff>
    <selfCollide>
                true
            </selfCollide>
  </gazebo>
  <transmission name="DarmSim_lowerTiltTop_trans" type="pr2_mechanism_model/SimpleTransmission">
    <actuator name="DarmSim_lowerTiltTop_motor"/>
    <joint name="DarmSim/lowerTiltTopJoint"/>
    <mechanicalReduction>1</mechanicalReduction>
    <motorTorqueConstant>1</motorTorqueConstant>
    <pulsesPerRevolution>90000</pulsesPerRevolution>
  </transmission>
  <link name="UPPER_TILT_UNIT">
    <inertial>
      <origin xyz="-0.00174164 0.02676162 -0.01954200"/>
      <mass value="0.68038877"/>
      <inertia ixx="0.00065547" ixy="0.00001112" ixz="-0.00000794" iyy="0.00064556" iyz="0.00008438" izz="0.00037446"/>
    </inertial>
    <visual>
      <material name="DarpaGrey"/>
      <origin rpy="0 0 0" xyz="0 0 0.0"/>
      <geometry>
        <mesh filename="package://arm_robot_model/models/componentSTL/upperTiltUnitLink.stl"/>
      </geometry>
    </visual>
    <collision>
      <origin rpy="0 0 0" xyz="0 0 0.0"/>
      <geometry>
        <mesh filename="package://arm_robot_model/models/collision/upperTiltUnitLink.stl"/>
      </geometry>
    </collision>
  </link>
  <gazebo reference="UPPER_TILT_UNIT">
    <material>
                PR2/Grey2
            </material>
    <turnGravityOff>
                true
            </turnGravityOff>
    <selfCollide>
                true
            </selfCollide>
  </gazebo>
  <transmission name="DarmSim_upperTilt_trans" type="pr2_mechanism_model/SimpleTransmission">
    <actuator name="DarmSim_upperTilt_motor"/>
    <joint name="DarmSim/UpperPanTilt/Pan"/>
    <mechanicalReduction>1</mechanicalReduction>
    <motorTorqueConstant>1</motorTorqueConstant>
    <pulsesPerRevolution>90000</pulsesPerRevolution>
  </transmission>
  <link name="HEAD">
    <inertial>
      <origin xyz="-0.00010270 0.12983722 0.01665482"/>
      <mass value="1.99572228"/>
      <inertia ixx="0.01220438" ixy="-0.00000904" ixz="0.00000750" iyy="0.00646285" iyz="-0.00066863" izz="0.00926422"/>
    </inertial>
    <visual>
      <material name="DarpaGrey"/>
      <origin rpy="0 0 0" xyz="0 0 0"/>
      <geometry>
        <mesh filename="package://arm_robot_model/models/componentSTL/head.stl"/>
      </geometry>
    </visual>
    <collision>
      <origin rpy="0 0 0" xyz="0 0 0"/>
      <geometry>
        <mesh filename="package://arm_robot_model/models/collision/head.stl"/>
      </geometry>
    </collision>
  </link>
  <gazebo reference="HEAD">
    <material>
                PR2/Grey2
            </material>
    <turnGravityOff>
                true
            </turnGravityOff>
    <selfCollide>
                true
            </selfCollide>
  </gazebo>
  <transmission name="DarmSim_headPitch_trans" type="pr2_mechanism_model/SimpleTransmission">
    <actuator name="DarmSim_headPitch_motor"/>
    <joint name="DarmSim/UpperPanTilt/Tilt"/>
    <mechanicalReduction>1</mechanicalReduction>
    <motorTorqueConstant>1</motorTorqueConstant>
    <pulsesPerRevolution>90000</pulsesPerRevolution>
  </transmission>
  <link name="XTION">
    <inertial>
      <origin xyz="0 0 0"/>
      <mass value="0.01"/>
      <inertia ixx="0.00001" ixy="0.0" ixz="0.0" iyy="0.00001" iyz="0.0" izz="0.00001"/>
    </inertial>
    <visual>
      <material name="DarpaGrey"/>
      <origin rpy="0 0 0" xyz="0 0 0"/>
      <geometry>
        <cylinder length="0.0000000001" radius="0.0000000001"/>
      </geometry>
    </visual>
    <collision>
      <origin xyz="0 0 0"/>
      <geometry>
        <box size="0.0000000001 0.0000000001 0.0000000001"/>
      </geometry>
    </collision>
  </link>
  <gazebo reference="XTION">
    <material>
                PR2/Grey2
            </material>
    <turnGravityOff>
                true
            </turnGravityOff>
    <selfCollide>
                true
            </selfCollide>
  </gazebo>
  <link name="BUMBLEBEE_LEFT_REAL">
    <inertial>
      <origin xyz="0 0 0"/>
      <mass value="0.01"/>
      <inertia ixx="0.00001" ixy="0.0" ixz="0.0" iyy="0.00001" iyz="0.0" izz="0.00001"/>
    </inertial>
    <visual>
      <material name="DarpaGrey"/>
      <origin rpy="0 0 0" xyz="0 0 0"/>
      <geometry>
        <box size=" 0.0000000001 0.0000000001 0.0000000001"/>
      </geometry>
    </visual>
    <collision>
      <origin xyz="0 0 0"/>
      <geometry>
        <box size="0.0000000001 0.0000000001 0.0000000001"/>
      </geometry>
    </collision>
  </link>
  <gazebo reference="BUMBLEBEE_LEFT_REAL">
    <material>
                PR2/Grey2
            </material>
    <turnGravityOff>
                true
            </turnGravityOff>
    <selfCollide>
                true
            </selfCollide>
  </gazebo>
  <link name="BUMBLEBEE_RIGHT">
    <inertial>
      <origin xyz="0 0 0"/>
      <mass value="0.01"/>
      <inertia ixx="0.00001" ixy="0.0" ixz="0.0" iyy="0.00001" iyz="0.0" izz="0.00001"/>
    </inertial>
    <visual>
      <material name="DarpaGrey"/>
      <origin rpy="0 0 0" xyz="0 0 0"/>
      <geometry>
        <box size=" 0.0000000001 0.0000000001 0.0000000001"/>
      </geometry>
    </visual>
    <collision>
      <origin xyz="0 0 0"/>
      <geometry>
        <box size=" 0.0000000001 0.0000000001 0.0000000001"/>
      </geometry>
    </collision>
  </link>
  <gazebo reference="BUMBLEBEE_RIGHT">
    <material>
                PR2/Grey2
            </material>
    <turnGravityOff>
                true
            </turnGravityOff>
    <selfCollide>
                true
            </selfCollide>
  </gazebo>
  <link name="PROSILICA">
    <inertial>
      <origin xyz="0 0 0"/>
      <mass value="0.01"/>
      <inertia ixx="0.00001" ixy="0.0" ixz="0.0" iyy="0.00001" iyz="0.0" izz="0.00001"/>
    </inertial>
    <visual>
      <material name="DarpaGrey"/>
      <origin rpy="0 0 0" xyz="0 0 0"/>
      <geometry>
        <box size=" 0.0000000001 0.0000000001 0.0000000001"/>
      </geometry>
    </visual>
    <collision>
      <origin xyz="0 0 0"/>
      <geometry>
        <box size=" 0.0000000001 0.0000000001 0.0000000001"/>
      </geometry>
    </collision>
  </link>
  <gazebo reference="PROSILICA">
    <material>
                PR2/Grey2
            </material>
    <turnGravityOff>
                true
            </turnGravityOff>
    <selfCollide>
                true
            </selfCollide>
  </gazebo>
  <joint name="LPAN" type="revolute">
    <parent link="TORSO"/>
    <child link="LOWER_PAN_UNIT"/>
    <origin rpy="1.57079632679 0 3.14159265359" xyz="0 .1292225 .52971"/>
    <axis xyz="0 -1 0"/>
    <limit effort="30" lower="-2.9" upper="2.9" velocity="3.27"/>
    <dynamics damping="0.301"/>
  </joint>
  <joint name="LTILT" type="revolute">
    <parent link="LOWER_PAN_UNIT"/>
    <child link="LOWER_TILT_BEAMS"/>
    <origin rpy="0 0 0" xyz="0 .127 0"/>
    <axis xyz="1 0 0"/>
    <limit effort="30" lower="-1.22" upper="1.22" velocity="3.27"/>
    <dynamics damping="0.301"/>
  </joint>
  <joint name="LTILT_FRONT" type="revolute">
    <parent link="LOWER_PAN_UNIT"/>
    <child link="LOWER_TILT_BEAMS_FRONT"/>
    <origin rpy="0 1.57079632679 0" xyz="0 0.127 0.04953"/>
    <axis xyz="0 0 1"/>
    <limit effort="30" lower="-1.22" upper="1.22" velocity="3.27"/>
    <dynamics damping="0.301"/>
    <mimic joint="LTILT" multiplier="1" offset="0"/>
  </joint>
  <gazebo>
    <joint:hinge name="DarmSim/lowerTiltFrontTopJoint">
      <body1>LOWER_TILT_BEAMS_FRONT</body1>
      <body2>LOWER_TILT_BEAMS_TOP</body2>
      <anchor>LOWER_TILT_BEAMS_TOP</anchor>
      <axis>-1 0 0</axis>
      <damping>0.301</damping>
      <anchorOffset>0 0 0.04953</anchorOffset>
    </joint:hinge>
  </gazebo>
  <joint name="LTILT_TOP" type="revolute">
    <parent link="LOWER_TILT_BEAMS"/>
    <child link="LOWER_TILT_BEAMS_TOP"/>
    <origin rpy="0 0 0" xyz="0 0.1524 0"/>
    <axis xyz="1 0 0"/>
    <limit effort="30" lower="-1.22" upper="1.22" velocity="3.27"/>
    <dynamics damping="0.301"/>
    <mimic joint="LTILT" multiplier="-1" offset="0"/>
  </joint>
  <joint name="UPAN" type="revolute">
    <parent link="LOWER_TILT_BEAMS_TOP"/>
    <child link="UPPER_TILT_UNIT"/>
    <origin rpy="0 0 0" xyz="0 .059182 .04953"/>
    <axis xyz="0 -1 0"/>
    <limit effort="30" lower="-1.55" upper="1.55" velocity="3.27"/>
    <dynamics damping="0.101"/>
  </joint>
  <joint name="UTILT" type="revolute">
    <parent link="UPPER_TILT_UNIT"/>
    <child link="HEAD"/>
    <origin rpy="0 0 0" xyz="0 0.04371 0"/>
    <axis xyz="1 0 0"/>
    <limit effort="30" lower="0.0" upper="1.3" velocity="3.27"/>
    <dynamics damping="0.101"/>
  </joint>
  <joint name="XtionJoint" type="fixed">
    <parent link="BUMBLEBEE_LEFT_REAL"/>
    <child link="XTION"/>
    <origin rpy="-0.019412 -0.003912 -0.002252" xyz="0.004063 0.059088 0.024217"/>
  </joint>
  <joint name="BumbleBee2LeftEyeJoint" type="fixed">
    <parent link="HEAD"/>
    <child link="BUMBLEBEE_LEFT_REAL"/>
    <origin rpy="0.023374 -0.004796 -3.135335" xyz="0.056291 0.131375 0.052073"/>
  </joint>
  <joint name="RightEyeJoint" type="fixed">
    <parent link="BUMBLEBEE_LEFT_REAL"/>
    <child link="BUMBLEBEE_RIGHT"/>
    <origin rpy="-0.003023 -0.004726 0.002817" xyz="0.121158 0.000685 -0.004150"/>
  </joint>
  <joint name="ProsilicaJoint" type="fixed">
    <parent link="BUMBLEBEE_LEFT_REAL"/>
    <child link="PROSILICA"/>
    <origin rpy="-0.040877 -0.015545 0.013051" xyz="0.060819 -0.058169 -0.016757"/>
  </joint>
  <!--  offset was -.2186555 before adding sin(45)*.186 which is needed to put shoulder in right place -->
  <link name="L_SHOULDER">
    <inertial>
      <origin xyz="-.00443422 0.1289039 -.00066489"/>
      <mass value="10.7677"/>
      <inertia ixx=".13488033" ixy="-.00213041" ixz="-.00012485" iyy=".11328369" iyz=".00068555" izz=".09046330"/>
    </inertial>
    <visual>
      <material name="DarpaGrey"/>
      <origin rpy="3.14159265359 0 0" xyz="0 .189 0"/>
      <geometry>
        <mesh filename="package://arm_robot_model/models/componentSTL/wamShoulderLink1.stl"/>
      </geometry>
    </visual>
    <collision>
      <origin rpy="3.14159265359 0 0" xyz="0 .189 0"/>
      <geometry>
        <mesh filename="package://arm_robot_model/models/collision/wamShoulderLink1.stl"/>
      </geometry>
    </collision>
  </link>
  <gazebo reference="L_SHOULDER">
    <material>
                PR2/Grey2
            </material>
    <turnGravityOff>
                true
            </turnGravityOff>
    <selfCollide>
                true
            </selfCollide>
  </gazebo>
  <transmission name="DarmSim_LArm_WAM_ShoulderYaw_trans" type="pr2_mechanism_model/SimpleTransmission">
    <actuator name="DarmSim_LArm_WAM_ShoulderYaw_motor"/>
    <joint name="DarmSim/LArm/WAM/YawJoint"/>
    <mechanicalReduction>1</mechanicalReduction>
    <motorTorqueConstant>1</motorTorqueConstant>
    <pulsesPerRevolution>90000</pulsesPerRevolution>
  </transmission>
  <link name="L_UPPER_ARM_IN_SHOULDER">
    <visual>
      <material name="DarpaGrey"/>
      <origin rpy="3.14159265359 0 0" xyz="0 0 0"/>
      <geometry>
        <mesh filename="package://arm_robot_model/models/componentSTL/wamUpperArmInShoulderLink2.stl"/>
      </geometry>
    </visual>
    <inertial>
      <origin xyz="-.00236981 .03105614 .01542114"/>
      <mass value="3.87493756"/>
      <inertia ixx=".02140958" ixy=".00027172" ixz=".00002461" iyy=".01377875" iyz="-.00181920" izz=".01558906"/>
    </inertial>
    <collision>
      <origin rpy="3.14159265359 0 0" xyz="0 0 0"/>
      <geometry>
        <mesh filename="package://arm_robot_model/models/collision/wamUpperArmInShoulderLink2.stl"/>
      </geometry>
    </collision>
  </link>
  <gazebo reference="L_UPPER_ARM_IN_SHOULDER">
    <material>
                PR2/Grey2
            </material>
    <turnGravityOff>
                true
            </turnGravityOff>
    <selfCollide>
                true
            </selfCollide>
  </gazebo>
  <transmission name="DarmSim_LArm_WAM_ShoulderPitch_trans" type="pr2_mechanism_model/SimpleTransmission">
    <actuator name="DarmSim_LArm_WAM_ShoulderPitch_motor"/>
    <joint name="L_Arm_ShoulderPitchJoint"/>
    <mechanicalReduction>1</mechanicalReduction>
    <motorTorqueConstant>1</motorTorqueConstant>
    <pulsesPerRevolution>90000</pulsesPerRevolution>
  </transmission>
  <link name="L_UPPER_ARM">
    <inertial>
      <origin xyz="-.03826 .20751 .00003"/>
      <mass value="1.80228141"/>
      <inertia ixx=".05911077" ixy="-.00249612" ixz=".00000738" iyy=".00324550" iyz="-.00001767" izz=".05927043"/>
    </inertial>
    <visual>
      <material name="DarpaGrey"/>
      <origin rpy="0 0 0" xyz="0 0 0"/>
      <geometry>
        <mesh filename="package://arm_robot_model/models/componentSTL/wamUpperArmLink3.stl"/>
      </geometry>
    </visual>
    <collision>
      <origin rpy="0 0 0" xyz="0 0 0"/>
      <geometry>
        <mesh filename="package://arm_robot_model/models/collision/wamUpperArmLink3.stl"/>
      </geometry>
    </collision>
  </link>
  <gazebo reference="L_UPPER_ARM">
    <material>
                PR2/Grey2
            </material>
    <turnGravityOff>
                true
            </turnGravityOff>
    <selfCollide>
                true
            </selfCollide>
  </gazebo>
  <transmission name="DarmSim_LArm_WAM_UpperArmYaw_trans" type="pr2_mechanism_model/SimpleTransmission">
    <actuator name="DarmSim_LArm_WAM_UpperArmYaw_motor"/>
    <joint name="L_Arm_ShoulderYawJoint"/>
    <mechanicalReduction>1</mechanicalReduction>
    <motorTorqueConstant>1</motorTorqueConstant>
    <pulsesPerRevolution>90000</pulsesPerRevolution>
  </transmission>
  <link name="L_FOREARM">
    <inertial>
      <origin xyz="0 0 0"/>
      <mass value="2.40016804"/>
      <origin rpy="0 0 0" xyz="-0.04001488 -.00022942 .13271662"/>
      <inertia ixx="0.01491672" ixy="0.00001741" ixz="-0.00150604" iyy="0.01482988" iyz="-0.00002109" izz="0.00294463"/>
    </inertial>
    <visual>
      <material name="DarpaGrey"/>
      <origin rpy="-3.14159265359 0 0" xyz="0 0 0"/>
      <geometry>
        <mesh filename="package://arm_robot_model/models/componentSTL/wamForeArmLink4.stl"/>
      </geometry>
    </visual>
    <collision>
      <origin rpy="-3.14159265359 0 0" xyz="0 0 0"/>
      <geometry>
        <mesh filename="package://arm_robot_model/models/collision/wamForeArmLink4.stl"/>
      </geometry>
    </collision>
  </link>
  <gazebo reference="L_FOREARM">
    <material>
                PR2/Grey2
            </material>
    <turnGravityOff>
                true
            </turnGravityOff>
    <selfCollide>
                true
            </selfCollide>
  </gazebo>
  <transmission name="DarmSim_LArm_WAM_ElbowPitch_trans" type="pr2_mechanism_model/SimpleTransmission">
    <actuator name="DarmSim_LArm_WAM_ElbowPitch_motor"/>
    <joint name="DarmSim/LArm/WAM/ElbowJoint"/>
    <mechanicalReduction>1</mechanicalReduction>
    <motorTorqueConstant>1</motorTorqueConstant>
    <pulsesPerRevolution>90000</pulsesPerRevolution>
  </transmission>
  <link name="L_UPPER_WRIST_YAW">
    <inertial>
      <origin xyz="0.00008921 0.00511217 0.00435824"/>
      <mass value="0.12376019"/>
      <inertia ixx="0.00005029" ixy="0.00000020" ixz="0.00007582" iyy="0.00007582" iyz="-0.00000359" izz="0.00006270"/>
    </inertial>
    <visual>
      <material name="DarpaGrey"/>
      <origin rpy="3.14159265359 0 0" xyz="0 0.02711 0"/>
      <geometry>
        <mesh filename="package://arm_robot_model/models/componentSTL/wamUpperWristYawLink5.stl"/>
      </geometry>
    </visual>
    <collision>
      <origin rpy="3.14159265359 0 0" xyz="0 0.02711 0"/>
      <geometry>
        <mesh filename="package://arm_robot_model/models/collision/wamUpperWristYawLink5.stl"/>
      </geometry>
    </collision>
  </link>
  <gazebo reference="L_UPPER_WRIST_YAW">
    <material>
                PR2/Grey2
            </material>
    <turnGravityOff>
                true
            </turnGravityOff>
    <selfCollide>
                true
            </selfCollide>
  </gazebo>
  <transmission name="DarmSim_LArm_WAM_UpperWristYaw_trans" type="pr2_mechanism_model/SimpleTransmission">
    <actuator name="DarmSim_LArm_WAM_UpperWristYaw_motor"/>
    <joint name="DarmSim/LArm/WAM/UpperWristYawJoint"/>
    <mechanicalReduction>1</mechanicalReduction>
    <motorTorqueConstant>1</motorTorqueConstant>
    <pulsesPerRevolution>90000</pulsesPerRevolution>
  </transmission>
  <link name="L_UPPER_WRIST_PITCH">
    <inertial>
      <origin rpy="0 0 0" xyz="-0.00012262 -0.01703194 0.02468336"/>
      <mass value="0.41797364"/>
      <inertia ixx="0.00055516" ixy="0.00000061" ixz="-0.00000074" iyy="0.00024367" iyz="-0.00004590" izz="0.00045358"/>
    </inertial>
    <visual>
      <material name="DarpaGrey"/>
      <origin rpy="1.57079632679 0 1.57079632679" xyz="0 0 0"/>
      <geometry>
        <mesh filename="package://arm_robot_model/models/componentSTL/wamUpperWristPitchLink6.stl"/>
      </geometry>
    </visual>
    <collision>
      <origin rpy="1.57079632679 0 1.57079632679" xyz="0 0 0"/>
      <geometry>
        <mesh filename="package://arm_robot_model/models/collision/wamUpperWristPitchLink6.stl"/>
      </geometry>
    </collision>
  </link>
  <gazebo reference="L_UPPER_WRIST_PITCH">
    <material>
                PR2/Grey2
            </material>
    <turnGravityOff>
                true
            </turnGravityOff>
    <selfCollide>
                true
            </selfCollide>
  </gazebo>
  <transmission name="DarmSim_LArm_WAM_UpperWristPitch_trans" type="pr2_mechanism_model/SimpleTransmission">
    <actuator name="DarmSim_LArm_WAM_UpperWristPitch_motor"/>
    <joint name="DarmSim/LArm/WAM/UpperWristPitchJoint"/>
    <mechanicalReduction>1</mechanicalReduction>
    <motorTorqueConstant>1</motorTorqueConstant>
    <pulsesPerRevolution>90000</pulsesPerRevolution>
  </transmission>
  <link name="L_LOWER_WRIST">
    <inertial>
      <origin xyz="0.00035500 -0.00499005 0.04864979"/>
      <mass value="0.63352875"/>
      <inertia ixx="0.00102103" ixy="0.00000775" ixz="-0.00001230" iyy="0.00080944" iyz="-0.00014417" izz="0.00068788"/>
    </inertial>
    <visual>
      <material name="DarpaGrey"/>
      <origin rpy="1.57079632679 0 0" xyz="0 0 0"/>
      <geometry>
        <mesh filename="package://arm_robot_model/models/componentSTL/wamLowerWristFTPalmLink7.stl"/>
      </geometry>
    </visual>
    <collision>
      <origin rpy="1.57079632679 0 0" xyz="0 0 0"/>
      <geometry>
        <mesh filename="package://arm_robot_model/models/collision/wamLowerWristFTPalmLink7.stl"/>
      </geometry>
    </collision>
  </link>
  <gazebo reference="L_LOWER_WRIST">
    <material>
                PR2/Grey2
            </material>
    <turnGravityOff>
                true
            </turnGravityOff>
    <selfCollide>
                true
            </selfCollide>
  </gazebo>
  <transmission name="DarmSim_LArm_WAM_LowerWristYaw_trans" type="pr2_mechanism_model/SimpleTransmission">
    <actuator name="DarmSim_LArm_WAM_LowerWristYaw_motor"/>
    <joint name="DarmSim/LArm/WAM/LowerWristYawJoint"/>
    <mechanicalReduction>1</mechanicalReduction>
    <motorTorqueConstant>1</motorTorqueConstant>
    <pulsesPerRevolution>90000</pulsesPerRevolution>
  </transmission>
  <link name="L_PALM"/>
  <link name="L_FORCE_TORQUE_SENSOR"/>
  <joint name="L_SFE" type="revolute">
    <parent link="TORSO"/>
    <child link="L_SHOULDER"/>
    <origin rpy="-1.57079632679 -1.57079632679 5.49778714378" xyz="-0.350177361 0.350177361 .37836125"/>
    <axis xyz="0 1.0 0"/>
    <limit effort="25" lower="-2.67" upper="2.66" velocity="3.27"/>
    <!--
            <safety_controller k_position="10000000" k_velocity="10000000" soft_lower_limit="-100.0" soft_upper_limit="100.0" />
-->
    <dynamics damping="1.0" friction="100.0"/>
  </joint>
  <joint name="L_SAA" type="revolute">
    <parent link="L_SHOULDER"/>
    <child link="L_UPPER_ARM_IN_SHOULDER"/>
    <!--<origin xyz="0 0 0" rpy="${0.5 * PI} 0 0"/>-->
    <origin rpy="1.57079632679 0 -1.570796" xyz="0 0 0"/>
    <axis xyz="0 -1 0"/>
    <limit effort="20" lower="-3.47" upper="0.4" velocity="3.27"/>
    <!--
            <safety_controller k_position="100" k_velocity="3" soft_lower_limit="-100.0" soft_upper_limit="100.0" />
-->
    <dynamics damping="1.0" friction="100.0"/>
  </joint>
  <joint name="L_HR" type="revolute">
    <parent link="L_UPPER_ARM_IN_SHOULDER"/>
    <child link="L_UPPER_ARM"/>
    <origin rpy="-1.57079632679 0 0.785398" xyz="0 0 0"/>
    <axis xyz="0 1.0 0"/>
    <limit effort="15" lower="-5.15" upper="0.46" velocity="3.27"/>
    <!--
            <safety_controller k_position="100" k_velocity="3" soft_lower_limit="-100.0" soft_upper_limit="100.0" />
-->
    <dynamics damping="1.0" friction="100.0"/>
  </joint>
  <joint name="L_EB" type="revolute">
    <parent link="L_UPPER_ARM"/>
    <child link="L_FOREARM"/>
    <origin rpy="1.57079632679 0 0.0" xyz="0.045 -0.55 0"/>
    <axis xyz="0 1 0"/>
    <limit effort="15" lower="-0.85" upper="3.11" velocity="3.27"/>
    <!--
            <safety_controller k_position="100" k_velocity="3" soft_lower_limit="-100.0" soft_upper_limit="100.0" />
-->
    <dynamics damping="1.0" friction="100.0"/>
  </joint>
  <joint name="L_WR" type="revolute">
    <parent link="L_FOREARM"/>
    <child link="L_UPPER_WRIST_YAW"/>
    <origin rpy="-1.57079632679 0 3.14159232679" xyz="-0.045 0 .3"/>
    <axis xyz="0 1.0 0"/>
    <limit effort="5" lower="0.36" upper="5.54" velocity="3.27"/>
    <!--
            <safety_controller k_position="100" k_velocity="3" soft_lower_limit="-100.0" soft_upper_limit="100.0" />
-->
    <dynamics damping="1.0" friction="100.0"/>
  </joint>
  <joint name="L_WFE" type="revolute">
    <parent link="L_UPPER_WRIST_YAW"/>
    <child link="L_UPPER_WRIST_PITCH"/>
    <origin rpy="1.57079632679 1.57079632679 0.0" xyz="0 0 0"/>
    <axis xyz="0 1 0"/>
    <limit effort="5" lower="-1.5" upper="1.54" velocity="3.27"/>
    <!-- 1.45 is a limit taken in from 1.5 due to saftey and differences between arms. -->
    <!--
            <safety_controller k_position="100" k_velocity="3" soft_lower_limit="-100.0" soft_upper_limit="100.0" />
-->
    <dynamics damping="1.0" friction="100.0"/>
  </joint>
  <joint name="L_WAA" type="revolute">
    <parent link="L_UPPER_WRIST_PITCH"/>
    <child link="L_LOWER_WRIST"/>
    <origin rpy="0 0 1.57079632679" xyz="0 0 0.04795"/>
    <axis xyz="0 0 -1.0"/>
    <limit effort="5" lower="-2.91" upper="3.04" velocity="3.27"/>
    <!-- 2.95 is a limit taken in from 3 due to saftey and differences between arms. -->
    <!--
            <safety_controller k_position="100" k_velocity="3" soft_lower_limit="-100.0" soft_upper_limit="100.0" />
-->
    <dynamics damping="1.0" friction="100.0"/>
  </joint>
  <joint name="L_Arm_ForceTorqueJoint" type="fixed">
    <parent link="L_LOWER_WRIST"/>
    <child link="L_FORCE_TORQUE_SENSOR"/>
    <origin rpy="0 0 1.57079632679" xyz="0 0 0.0131834"/>
    <!-- 0.0131834 = .0059834 from wrist to f-t + .0072 from ft to sensor origin-->
  </joint>
  <joint name="L_Arm_PalmJoint" type="fixed">
    <parent link="L_LOWER_WRIST"/>
    <child link="L_PALM"/>
    <origin rpy="0 0 3.14159265359" xyz="0 0 0.1033"/>
  </joint>
  <link name="L_HAND_M_FINGER_KNUCKLE_2">
    <visual>
      <material name="DarpaGrey"/>
      <origin rpy="3.14159265359 1.57079632679 0" xyz="0 0 0"/>
      <geometry>
        <mesh filename="package://arm_robot_model/models/componentSTL/secondFingerLink.stl"/>
      </geometry>
    </visual>
    <inertial>
      <origin xyz=".031720 .001070 -.000586"/>
      <mass value="0.057957"/>
      <inertia ixx="0.00000461" ixy="0.00000003" ixz="0.00000164" iyy="0.00003590" iyz="0.00000004" izz="0.00003682"/>
    </inertial>
    <collision>
      <origin rpy="3.14159265359 1.57079632679 0" xyz="0 0 0"/>
      <geometry>
        <mesh filename="package://arm_robot_model/models/collision/secondFingerLink.stl"/>
      </geometry>
      <mu1 value="50000.0"/>
      <mu2 value="50000.0"/>
      <kp value="1000000.0"/>
      <kd value="1.0"/>
    </collision>
  </link>
  <gazebo reference="L_HAND_M_FINGER_KNUCKLE_2">
    <material>
                PR2/Grey2
            </material>
    <turnGravityOff>
                true
            </turnGravityOff>
    <selfCollide>
                true
            </selfCollide>
  </gazebo>
  <transmission name="DarmSim_LArm_BHand_FingerMKnuckleTwo_trans" type="pr2_mechanism_model/SimpleTransmission">
    <actuator name="DarmSim_LArm_BHand_FingerMKnuckleTwo_motor"/>
    <joint name="L_Arm_M_Finger_KnuckleTwoJoint"/>
    <mechanicalReduction>1</mechanicalReduction>
    <motorTorqueConstant>1</motorTorqueConstant>
    <pulsesPerRevolution>90000</pulsesPerRevolution>
  </transmission>
  <link name="L_HAND_M_FINGER_KNUCKLE_3">
    <visual>
      <material name="DarpaGrey"/>
      <origin rpy="0 1.57079632679 0" xyz="0 0 0"/>
      <geometry>
        <mesh filename="package://arm_robot_model/models/componentSTL/thirdFingerLink.stl"/>
      </geometry>
    </visual>
    <inertial>
      <origin xyz="0.01970974 0.00182016 0.00020041"/>
      <mass value="0.03421781"/>
      <inertia ixx="0.00000287" ixy="0.00000091" ixz="-0.00000007" iyy="0.00001329" iyz="-0.00000002" izz="0.00001214"/>
    </inertial>
    <collision>
      <origin rpy="0 1.57079632679 0" xyz="0 0 0"/>
      <geometry>
        <mesh filename="package://arm_robot_model/models/collision/thirdFingerLink.stl"/>
      </geometry>
      <mu1 value="50000.0"/>
      <mu2 value="50000.0"/>
      <kp value="1000000.0"/>
      <kd value="1.0"/>
    </collision>
  </link>
  <gazebo reference="L_HAND_M_FINGER_KNUCKLE_3">
    <material>
                PR2/Grey2
            </material>
    <turnGravityOff>
                true
            </turnGravityOff>
    <selfCollide>
                true
            </selfCollide>
  </gazebo>
  <transmission name="DarmSim_LArm_BHand_FingerMKnuckleThree_trans" type="pr2_mechanism_model/SimpleTransmission">
    <actuator name="DarmSim_LArm_BHand_FingerMKnuckleThree_motor"/>
    <joint name="L_Arm_M_Finger_KnuckleThreeJoint"/>
    <mechanicalReduction>1</mechanicalReduction>
    <motorTorqueConstant>1</motorTorqueConstant>
    <pulsesPerRevolution>90000</pulsesPerRevolution>
  </transmission>
  <link name="L_HAND_M_FINGER_TIP"/>
  <joint name="L_MF" type="revolute">
    <parent link="L_LOWER_WRIST"/>
    <child link="L_HAND_M_FINGER_KNUCKLE_2"/>
    <origin rpy="-1.57079632679 -0.0429350996 -1.57079632679" xyz="0 -0.05 0.09938"/>
    <axis xyz="0 0 -1"/>
    <limit effort="1" lower="0" upper="2.12232037299" velocity="3.27"/>
    <dynamics damping="0.005" friction="100.0"/>
  </joint>
  <joint name="L_MF2" type="revolute">
    <parent link="L_HAND_M_FINGER_KNUCKLE_2"/>
    <child link="L_HAND_M_FINGER_KNUCKLE_3"/>
    <origin rpy="0 0 0" xyz="0.07 0 0"/>
    <!--<origin xyz="0.07 0 0" rpy="0 0 -0.733038286"/>-->
    <axis xyz="0 0 -1"/>
    <limit effort="1" lower="0" upper="0.907571214" velocity="3.27"/>
    <dynamics damping="0.005" friction="100.0"/>
    <!--<mimic joint="${side}_${number}F" multiplier="1" offset="0"/>-->
  </joint>
  <joint name="L_MF3" type="fixed">
    <parent link="L_HAND_M_FINGER_KNUCKLE_3"/>
    <child link="L_HAND_M_FINGER_TIP"/>
    <origin rpy="0 0 0" xyz="0.056 0 0"/>
  </joint>
  <link name="L_HAND_L_FINGER_KNUCKLE_1">
    <visual>
      <material name="DarpaGrey"/>
      <origin rpy="1.57079632679 0 -1.57079632679" xyz="0 0 0"/>
      <geometry>
        <mesh filename="package://arm_robot_model/models/componentSTL/firstFingerLink.stl"/>
      </geometry>
      <mu1 value="50000.0"/>
      <mu2 value="50000.0"/>
      <kp value="1000000.0"/>
      <kd value="1.0"/>
    </visual>
    <inertial>
      <origin xyz="0.03201666 -0.00086502 0.00890075"/>
      <mass value="0.16252678"/>
      <inertia ixx="0.00002567" ixy="-0.00000146" ixz="0.00001128" iyy="0.00008818" iyz="-0.00000094" izz="0.00007827"/>
    </inertial>
    <collision>
      <origin rpy="1.57079632679 0 -1.57079632679" xyz="0 0 0"/>
      <geometry>
        <mesh filename="package://arm_robot_model/models/collision/firstFingerLink.stl"/>
      </geometry>
    </collision>
  </link>
  <gazebo reference="L_HAND_L_FINGER_KNUCKLE_1">
    <material>
                PR2/Grey2
            </material>
    <turnGravityOff>
                true
            </turnGravityOff>
    <selfCollide>
                true
            </selfCollide>
  </gazebo>
  <transmission name="DarmSim_LArm_BHand_FingerOneKnuckleOne_trans" type="pr2_mechanism_model/SimpleTransmission">
    <actuator name="DarmSim_LArm_BHand_FingerOneKnuckleOne_motor"/>
    <joint name="L_Arm_FingerOne_KnuckleOneJoint"/>
    <mechanicalReduction>1</mechanicalReduction>
    <motorTorqueConstant>1</motorTorqueConstant>
    <pulsesPerRevolution>90000</pulsesPerRevolution>
  </transmission>
  <link name="L_HAND_L_FINGER_KNUCKLE_2">
    <visual>
      <material name="DarpaGrey"/>
      <origin rpy="3.14159265359 1.57079632679 0" xyz="0 0 0"/>
      <geometry>
        <mesh filename="package://arm_robot_model/models/componentSTL/secondFingerLink.stl"/>
      </geometry>
    </visual>
    <inertial>
      <origin xyz=".031720 .001070 -.000586"/>
      <mass value="0.057957"/>
      <inertia ixx="0.00000461" ixy="0.00000003" ixz="0.00000164" iyy="0.00003590" iyz="0.00000004" izz="0.00003682"/>
    </inertial>
    <collision>
      <origin rpy="3.14159265359 1.57079632679 0" xyz="0 0 0"/>
      <geometry>
        <mesh filename="package://arm_robot_model/models/collision/secondFingerLink.stl"/>
      </geometry>
      <mu1 value="50000.0"/>
      <mu2 value="50000.0"/>
      <kp value="1000000.0"/>
      <kd value="1.0"/>
    </collision>
  </link>
  <gazebo reference="L_HAND_L_FINGER_KNUCKLE_2">
    <material>
                PR2/Grey2
            </material>
    <turnGravityOff>
                true
            </turnGravityOff>
    <selfCollide>
                true
            </selfCollide>
  </gazebo>
  <transmission name="DarmSim_LArm_BHand_FingerLKnuckleTwo_trans" type="pr2_mechanism_model/SimpleTransmission">
    <actuator name="DarmSim_LArm_BHand_FingerLKnuckleTwo_motor"/>
    <joint name="L_Arm_L_Finger_KnuckleTwoJoint"/>
    <mechanicalReduction>1</mechanicalReduction>
    <motorTorqueConstant>1</motorTorqueConstant>
    <pulsesPerRevolution>90000</pulsesPerRevolution>
  </transmission>
  <link name="L_HAND_L_FINGER_KNUCKLE_3">
    <visual>
      <material name="DarpaGrey"/>
      <origin rpy="0 1.57079632679 0" xyz="0 0 0"/>
      <geometry>
        <mesh filename="package://arm_robot_model/models/componentSTL/thirdFingerLink.stl"/>
      </geometry>
    </visual>
    <inertial>
      <origin xyz="0.01970974 0.00182016 0.00020041"/>
      <mass value="0.03421781"/>
      <inertia ixx="0.00000287" ixy="0.00000091" ixz="-0.00000007" iyy="0.00001329" iyz="-0.00000002" izz="0.00001214"/>
    </inertial>
    <collision>
      <origin rpy="0 1.57079632679 0" xyz="0 0 0"/>
      <geometry>
        <mesh filename="package://arm_robot_model/models/collision/thirdFingerLink.stl"/>
      </geometry>
      <mu1 value="50000.0"/>
      <mu2 value="50000.0"/>
      <kp value="1000000.0"/>
      <kd value="1.0"/>
    </collision>
  </link>
  <gazebo reference="L_HAND_L_FINGER_KNUCKLE_3">
    <material>
                PR2/Grey2
            </material>
    <turnGravityOff>
                true
            </turnGravityOff>
    <selfCollide>
                true
            </selfCollide>
  </gazebo>
  <transmission name="DarmSim_LArm_BHand_FingerLKnuckleThree_trans" type="pr2_mechanism_model/SimpleTransmission">
    <actuator name="DarmSim_LArm_BHand_FingerLKnuckleThree_motor"/>
    <joint name="L_Arm_L_Finger_KnuckleThreeJoint"/>
    <mechanicalReduction>1</mechanicalReduction>
    <motorTorqueConstant>1</motorTorqueConstant>
    <pulsesPerRevolution>90000</pulsesPerRevolution>
  </transmission>
  <link name="L_HAND_L_FINGER_TIP"/>
  <joint name="L_LF" type="revolute">
    <parent link="L_HAND_L_FINGER_KNUCKLE_1"/>
    <child link="L_HAND_L_FINGER_KNUCKLE_2"/>
    <origin rpy="-1.57079632679 -0.0429350996 0" xyz=".05 0 0.02140"/>
    <axis xyz="0 0 -1"/>
    <limit effort="1" lower="0" upper="2.12232037299" velocity="3.27"/>
    <dynamics damping="0.005" friction="100.0"/>
  </joint>
  <joint name="L_LF2" type="revolute">
    <parent link="L_HAND_L_FINGER_KNUCKLE_2"/>
    <child link="L_HAND_L_FINGER_KNUCKLE_3"/>
    <origin rpy="0 0 0" xyz="0.07 0 0"/>
    <!--<origin xyz="0.07 0 0" rpy="0 0 -0.733038286"/>-->
    <axis xyz="0 0 -1"/>
    <limit effort="1" lower="0" upper="0.907571214" velocity="3.27"/>
    <dynamics damping="0.005" friction="100.0"/>
    <!--<mimic joint="${side}_${number}F" multiplier="1" offset="0"/>-->
  </joint>
  <joint name="L_LF3" type="fixed">
    <parent link="L_HAND_L_FINGER_KNUCKLE_3"/>
    <child link="L_HAND_L_FINGER_TIP"/>
    <origin rpy="0 0 0" xyz="0.056 0 0"/>
  </joint>
  <link name="L_HAND_R_FINGER_KNUCKLE_1">
    <visual>
      <material name="DarpaGrey"/>
      <origin rpy="1.57079632679 0 -1.57079632679" xyz="0 0 0"/>
      <geometry>
        <mesh filename="package://arm_robot_model/models/componentSTL/firstFingerLink.stl"/>
      </geometry>
    </visual>
    <inertial>
      <origin xyz="0.03201666 -0.00086502 0.00890075"/>
      <mass value="0.16252678"/>
      <inertia ixx="0.00002567" ixy="-0.00000146" ixz="0.00001128" iyy="0.00008818" iyz="-0.00000094" izz="0.00007827"/>
    </inertial>
    <collision>
      <origin rpy="1.57079632679 0 -1.57079632679" xyz="0 0 0"/>
      <geometry>
        <mesh filename="package://arm_robot_model/models/collision/firstFingerLink.stl"/>
      </geometry>
    </collision>
  </link>
  <gazebo reference="L_HAND_R_FINGER_KNUCKLE_1">
    <material>
                PR2/Grey2
            </material>
    <turnGravityOff>
                true
            </turnGravityOff>
    <selfCollide>
                true
            </selfCollide>
  </gazebo>
  <transmission name="DarmSim_LArm_BHand_FingerTwoKnuckleOne_trans" type="pr2_mechanism_model/SimpleTransmission">
    <actuator name="DarmSim_LArm_BHand_FingerTwoKnuckleOne_motor"/>
    <joint name="L_Arm_FingerTwo_KnuckleOneJoint"/>
    <mechanicalReduction>1</mechanicalReduction>
    <motorTorqueConstant>1</motorTorqueConstant>
    <pulsesPerRevolution>90000</pulsesPerRevolution>
  </transmission>
  <link name="L_HAND_R_FINGER_KNUCKLE_2">
    <visual>
      <material name="DarpaGrey"/>
      <origin rpy="3.14159265359 1.57079632679 0" xyz="0 0 0"/>
      <geometry>
        <mesh filename="package://arm_robot_model/models/componentSTL/secondFingerLink.stl"/>
      </geometry>
    </visual>
    <inertial>
      <origin xyz=".031720 .001070 -.000586"/>
      <mass value="0.057957"/>
      <inertia ixx="0.00000461" ixy="0.00000003" ixz="0.00000164" iyy="0.00003590" iyz="0.00000004" izz="0.00003682"/>
    </inertial>
    <collision>
      <origin rpy="3.14159265359 1.57079632679 0" xyz="0 0 0"/>
      <geometry>
        <mesh filename="package://arm_robot_model/models/collision/secondFingerLink.stl"/>
      </geometry>
      <mu1 value="50000.0"/>
      <mu2 value="50000.0"/>
      <kp value="1000000.0"/>
      <kd value="1.0"/>
    </collision>
  </link>
  <gazebo reference="L_HAND_R_FINGER_KNUCKLE_2">
    <material>
                PR2/Grey2
            </material>
    <turnGravityOff>
                true
            </turnGravityOff>
    <selfCollide>
                true
            </selfCollide>
  </gazebo>
  <transmission name="DarmSim_LArm_BHand_FingerRKnuckleTwo_trans" type="pr2_mechanism_model/SimpleTransmission">
    <actuator name="DarmSim_LArm_BHand_FingerRKnuckleTwo_motor"/>
    <joint name="L_Arm_R_Finger_KnuckleTwoJoint"/>
    <mechanicalReduction>1</mechanicalReduction>
    <motorTorqueConstant>1</motorTorqueConstant>
    <pulsesPerRevolution>90000</pulsesPerRevolution>
  </transmission>
  <link name="L_HAND_R_FINGER_KNUCKLE_3">
    <visual>
      <material name="DarpaGrey"/>
      <origin rpy="0 1.57079632679 0" xyz="0 0 0"/>
      <geometry>
        <mesh filename="package://arm_robot_model/models/componentSTL/thirdFingerLink.stl"/>
      </geometry>
    </visual>
    <inertial>
      <origin xyz="0.01970974 0.00182016 0.00020041"/>
      <mass value="0.03421781"/>
      <inertia ixx="0.00000287" ixy="0.00000091" ixz="-0.00000007" iyy="0.00001329" iyz="-0.00000002" izz="0.00001214"/>
    </inertial>
    <collision>
      <origin rpy="0 1.57079632679 0" xyz="0 0 0"/>
      <geometry>
        <mesh filename="package://arm_robot_model/models/collision/thirdFingerLink.stl"/>
      </geometry>
      <mu1 value="50000.0"/>
      <mu2 value="50000.0"/>
      <kp value="1000000.0"/>
      <kd value="1.0"/>
    </collision>
  </link>
  <gazebo reference="L_HAND_R_FINGER_KNUCKLE_3">
    <material>
                PR2/Grey2
            </material>
    <turnGravityOff>
                true
            </turnGravityOff>
    <selfCollide>
                true
            </selfCollide>
  </gazebo>
  <transmission name="DarmSim_LArm_BHand_FingerRKnuckleThree_trans" type="pr2_mechanism_model/SimpleTransmission">
    <actuator name="DarmSim_LArm_BHand_FingerRKnuckleThree_motor"/>
    <joint name="L_Arm_R_Finger_KnuckleThreeJoint"/>
    <mechanicalReduction>1</mechanicalReduction>
    <motorTorqueConstant>1</motorTorqueConstant>
    <pulsesPerRevolution>90000</pulsesPerRevolution>
  </transmission>
  <link name="L_HAND_R_FINGER_TIP"/>
  <joint name="L_RF" type="revolute">
    <parent link="L_HAND_R_FINGER_KNUCKLE_1"/>
    <child link="L_HAND_R_FINGER_KNUCKLE_2"/>
    <origin rpy="-1.57079632679 -0.0429350996 0" xyz=".05 0 0.02140"/>
    <axis xyz="0 0 -1"/>
    <limit effort="1" lower="0" upper="2.12232037299" velocity="3.27"/>
    <dynamics damping="0.005" friction="100.0"/>
  </joint>
  <joint name="L_RF2" type="revolute">
    <parent link="L_HAND_R_FINGER_KNUCKLE_2"/>
    <child link="L_HAND_R_FINGER_KNUCKLE_3"/>
    <origin rpy="0 0 0" xyz="0.07 0 0"/>
    <!--<origin xyz="0.07 0 0" rpy="0 0 -0.733038286"/>-->
    <axis xyz="0 0 -1"/>
    <limit effort="1" lower="0" upper="0.907571214" velocity="3.27"/>
    <dynamics damping="0.005" friction="100.0"/>
    <!--<mimic joint="${side}_${number}F" multiplier="1" offset="0"/>-->
  </joint>
  <joint name="L_RF3" type="fixed">
    <parent link="L_HAND_R_FINGER_KNUCKLE_3"/>
    <child link="L_HAND_R_FINGER_TIP"/>
    <origin rpy="0 0 0" xyz="0.056 0 0"/>
  </joint>
  <joint name="L_FR" type="revolute">
    <parent link="L_LOWER_WRIST"/>
    <child link="L_HAND_L_FINGER_KNUCKLE_1"/>
    <origin rpy="0 0 1.57079632679" xyz=".02497 0 0.07798"/>
    <axis xyz="0 0 -1"/>
    <limit effort="1" lower="0" upper="3.14159265359" velocity="3.27"/>
    <dynamics damping="0.005" friction="100.0"/>
  </joint>
  <joint name="L_FR2" type="revolute">
    <parent link="L_LOWER_WRIST"/>
    <child link="L_HAND_R_FINGER_KNUCKLE_1"/>
    <origin rpy="0 0 1.57079632679" xyz="-.02497 0 0.07798"/>
    <axis xyz="0 0 1"/>
    <limit effort="1" lower="0" upper="3.14159265359" velocity="3.27"/>
    <dynamics damping="0.005" friction="100.0"/>
    <mimic joint="L_FR" multiplier="1" offset="0"/>
  </joint>
</robot>

